<div id="wrapper">
    <div id="content">
        <h2 class="challenge-title">ðŸš€ Handle a Rejected Promise with catch</h2>
        <div id="dynamic">
            <html><head></head><body><div><section id="description">
<p><code>catch</code> is the method used when your promise has been rejected. It is executed immediately after a promise&apos;s <code>reject</code> method is called. Here&#x2019;s the syntax:</p><p></p><pre class=" language-js">myPromise.catch(error =&gt; {
  // do something with the error.
});
</pre><p></p>
<p><code>error</code> is the argument passed in to the <code>reject</code> method.</p>
<p><strong>Note:</strong> the <code>then</code> and <code>catch</code> methods can be chained to the promise declaration if you choose.</p>
</section></div><hr><div><section id="instructions">
<p>Add the <code>catch</code> method to your promise. Use <code>error</code> as the parameter of its callback function and log <code>error</code> to the console.</p></section></div><hr></body></html>
        </div>
        <div id="challenges">
            <ul>
                <li>ðŸ§ª You should call the <code>catch</code> method on the promise.</li><li>ðŸ§ª Your <code>catch</code> method should have a callback function with <code>error</code> as its parameter.</li><li>ðŸ§ª You should log <code>error</code> to the console.</li>
            </ul>
        </div>
    </div>
</div>